1.So we don't have to write the try-catch block repeatedly
2. const getTask = asyncWrapper(async (req, res, next) => {  
  const { id: taskID } = req.params;  
  const task = await Task.findOne({ _id: taskID });  
  if (!task) {  
    return next(new CustomAPIError(`No task with id: ${taskID}`, 404))
  }  
  res.status(200).json({ task });  
});  
